<?xml version="1.0" encoding="utf-8"?>
<robot
  name="robot_description">

  <link
    name="base_link">
    <inertial>
      <origin
        xyz="-0.033659 0.024669 0.55033"
        rpy="0 0 0" />
      <mass
        value="0.82355" />
      <inertia
        ixx="0.00056474"
        ixy="2.1447E-06"
        ixz="7.5818E-07"
        iyy="0.0007493"
        iyz="3.225E-07"
        izz="0.0002766" />
    </inertial>
    <visual>
      <origin
        xyz="0 0.129 0.049"
        rpy="0 0 0.002" />
      <geometry>
        <mesh
          filename="package://robot_description/meshes/base_link.STL" />
      </geometry>
      <material
        name="">
        <color
          rgba="0 0.4 0.4 1" />
      </material>
    </visual>
    <collision>
      <origin
        xyz="0 0.129 0.049"
        rpy="0 0 0.002" />
      <geometry>
        <mesh
          filename="package://robot_description/meshes/base_link.STL" />
      </geometry>
    </collision>
  </link>

  <link
    name="left_wheel">
    <visual>
      <geometry>
        <cylinder length="0.015" radius="0.035" />
      </geometry>
      <origin rpy="1.57075 0 1.57075" xyz="0 0 0" />
      <material
        name="">
        <color rgba="0 0 0 1" />
      </material>
    </visual>
    <collision>
      <geometry>
        <cylinder length="0.015" radius="0.035" />
      </geometry>
      <origin rpy="1.57075 0 1.57075" xyz="0 0 0" />
    </collision>
    <inertial>
      <origin xyz="0 0 0" rpy="1.57075 0 0" />
      <mass value="0.5" />
      <inertia ixx="0.000226531" ixy="0" ixz="0" iyy="0.000226531" iyz="0" izz="0.000226531" />
    </inertial>
  </link>

  <joint name="left_joint" type="continuous">
    <parent link="base_link" />
    <child link="left_wheel" />
    <origin rpy="0 0 1.57075" xyz="0.005 0.075 0.03" />
    <axis xyz="0 1 0" />
  </joint>

  <link
    name="right_wheel">
    <visual>
      <geometry>
        <cylinder length="0.015" radius="0.035" />
      </geometry>
      <origin rpy="-1.57075 0 -1.57075" xyz="0 0 0" />
      <material
        name="">
        <color rgba="0 0 0 1" />
      </material>
    </visual>
    <collision>
      <geometry>
        <cylinder length="0.015" radius="0.035" />
      </geometry>
      <origin rpy="-1.57075 0 -1.57075" xyz="0 0 0" />
    </collision>
    <inertial>
      <origin xyz="0 0 0" rpy="1.57075 0 0" />
      <mass value="0.5" />
      <inertia ixx="0.000226531" ixy="0" ixz="0" iyy="0.000226531" iyz="0" izz="0.000226531" />
    </inertial>
  </link>

  <joint name="right_joint" type="continuous">
    <parent link="base_link" />
    <child link="right_wheel" />
    <origin rpy="0 0 -1.57075" xyz="-0.005 -0.075 0.03" />
    <axis xyz="0 1 0" />
  </joint>

  <link
    name="back_caster">
    
    <visual>
      <geometry>
        <sphere radius="0.02"/>
      </geometry>
      <material name="Cyan">
        <color rgba="0 1.0 1.0 1.0"/>
      </material>
    </visual>

    <collision>
      <origin xyz="0 0 0" rpy="0 0 0"/>
      <geometry>
        <sphere radius="0.02"/>
      </geometry>
    </collision>

    <inertial>
      <mass value="0.5"/>
      <inertia ixx="0.000226531" ixy="0" ixz="0" iyy="0.000226531" iyz="0" izz="0.000226531"/>
    </inertial>

  </link>

  <joint
    name="back_caster_joint" type="fixed">
    <parent link="base_link"/>
    <child link="back_caster"/>
    <origin xyz="-0.1 0 0.01" rpy="0 0 0"/>
  </joint>

  <link
    name="rplidar">

    <visual>
      <geometry>
        <box size=" 0.01 0.01 0.01"></box>
      </geometry>
      <origin rpy="0 0 0" xyz="0 0 0" />
      <material
        name="">
        <color rgba="1 1 1 1" />
      </material>
    </visual>
  </link>
  <joint
    name="rplidar_joint" type="fixed">
    <parent link="base_link" />
    <child link="rplidar" />
    <origin xyz="-0.04 0 0.18" rpy="0 0 0" />
  </joint>

  <gazebo reference="rplidar">
    <sensor name="lidar" type="ray">
      <always_on>true</always_on>
      <visualize>true</visualize>
      <update_rate>5</update_rate>
      <ray>
        <scan>
          <horizontal>
            <samples>360</samples>
            <resolution>1.000000</resolution>
            <min_angle>0.000000</min_angle>
            <max_angle>6.280000</max_angle>
          </horizontal>
        </scan>
        <range>
          <min>0.120000</min>
          <max>3.5</max>
          <resolution>0.015000</resolution>
        </range>
        <noise>
          <type>gaussian</type>
          <mean>0.0</mean>
          <stddev>0.01</stddev>
        </noise>
      </ray>
      <plugin name="scan" filename="libgazebo_ros_ray_sensor.so">
        <ros>
          <remapping>~/out:=scan</remapping>
        </ros>
        <output_type>sensor_msgs/LaserScan</output_type>
        <frame_name>rplidar</frame_name>
      </plugin>
    </sensor>
  </gazebo>

  <link
    name="camera_link">
    <visual>
      <geometry>
        <box size=" 0.01 0.01 0.01"></box>
      </geometry>
      <origin rpy="0 0 0" xyz="0 0 0" />
      <material
        name="">
        <color rgba="1 1 1 1" />
      </material>
    </visual>
  </link>

  <joint
    name="camera_joint" type="fixed">
    <parent link="base_link" />
    <child link="camera_link" />
    <origin xyz="0.08 0 0.14" rpy="0 0 0" />
  </joint>

  <gazebo reference="camera_link">
    <sensor name="depth_camera" type="depth">
      <visualize>true</visualize>
      <update_rate>30.0</update_rate>
      <camera name="camera">
        <horizontal_fov>1.047198</horizontal_fov>
        <image>
          <width>640</width>
          <height>480</height>
          <format>R8G8B8</format>
        </image>
        <clip>
          <near>0.05</near>
          <far>3</far>
        </clip>
      </camera>
      <plugin name="depth_camera_controller" filename="libgazebo_ros_camera.so">
        <baseline>0.2</baseline>
        <alwaysOn>true</alwaysOn>
        <updateRate>0.0</updateRate>
        <frame_name>camera_link</frame_name>
        <pointCloudCutoff>0.5</pointCloudCutoff>
        <pointCloudCutoffMax>3.0</pointCloudCutoffMax>
        <distortionK1>0</distortionK1>
        <distortionK2>0</distortionK2>
        <distortionK3>0</distortionK3>
        <distortionT1>0</distortionT1>
        <distortionT2>0</distortionT2>
        <CxPrime>0</CxPrime>
        <Cx>0</Cx>
        <Cy>0</Cy>
        <focalLength>0</focalLength>
        <hackBaseline>0</hackBaseline>
      </plugin>
    </sensor>
  </gazebo>


  <gazebo>
    <plugin name='diff_drive' filename='libgazebo_ros_diff_drive.so'>
      <ros>
        <namespace>/demo</namespace>
      </ros>

      <!-- wheels -->
      <left_joint>left_joint</left_joint>
      <right_joint>right_joint</right_joint>

      <!-- kinematics -->
      <wheel_separation>0.4</wheel_separation>
      <wheel_diameter>0.2</wheel_diameter>

      <!-- limits -->
      <max_wheel_torque>20</max_wheel_torque>
      <max_wheel_acceleration>1.0</max_wheel_acceleration>

      <!-- output -->
      <publish_odom>true</publish_odom>
      <publish_odom_tf>false</publish_odom_tf>
      <publish_wheel_tf>true</publish_wheel_tf>

      <odometry_frame>odom</odometry_frame>
      <robot_base_frame>base_link</robot_base_frame>
    </plugin>
  </gazebo>

  <link
    name="imu_link">
    <visual>
      <geometry>
        <box size=" 0.01 0.01 0.01"></box>
      </geometry>
      <origin rpy="0 0 0" xyz="0 0 0" />
      <material
        name="">
        <color rgba="1 1 1 1" />
      </material>
    </visual>
  </link>

  <joint
    name="imu_joint" type="fixed">
    <parent link="base_link" />
    <child link="imu_link" />
    <origin xyz="0 0 0.12" />
  </joint>

  <gazebo reference="imu_link">
    <sensor name="imu_sensor" type="imu">
      <plugin filename="libgazebo_ros_imu_sensor.so" name="imu_plugin">
        <ros>
          <namespace>/demo</namespace>
          <remapping>~/out:=imu</remapping>
        </ros>
        <initial_orientation_as_reference>false</initial_orientation_as_reference>
      </plugin>
      <always_on>true</always_on>
      <update_rate>100</update_rate>
      <visualize>true</visualize>
      <imu>
        <angular_velocity>
          <x>
            <noise type="gaussian">
              <mean>0.0</mean>
              <stddev>2e-4</stddev>
              <bias_mean>0.0000075</bias_mean>
              <bias_stddev>0.0000008</bias_stddev>
            </noise>
          </x>
          <y>
            <noise type="gaussian">
              <mean>0.0</mean>
              <stddev>2e-4</stddev>
              <bias_mean>0.0000075</bias_mean>
              <bias_stddev>0.0000008</bias_stddev>
            </noise>
          </y>
          <z>
            <noise type="gaussian">
              <mean>0.0</mean>
              <stddev>2e-4</stddev>
              <bias_mean>0.0000075</bias_mean>
              <bias_stddev>0.0000008</bias_stddev>
            </noise>
          </z>
        </angular_velocity>
        <linear_acceleration>
          <x>
            <noise type="gaussian">
              <mean>0.0</mean>
              <stddev>1.7e-2</stddev>
              <bias_mean>0.1</bias_mean>
              <bias_stddev>0.001</bias_stddev>
            </noise>
          </x>
          <y>
            <noise type="gaussian">
              <mean>0.0</mean>
              <stddev>1.7e-2</stddev>
              <bias_mean>0.1</bias_mean>
              <bias_stddev>0.001</bias_stddev>
            </noise>
          </y>
          <z>
            <noise type="gaussian">
              <mean>0.0</mean>
              <stddev>1.7e-2</stddev>
              <bias_mean>0.1</bias_mean>
              <bias_stddev>0.001</bias_stddev>
            </noise>
          </z>
        </linear_acceleration>
      </imu>
    </sensor>
  </gazebo>

</robot>