<?xml version="1.0"?>
<robot name="turtlebot3_waffle_jpc2_visual" xmlns:xacro="http://ros.org/wiki/xacro">


<!-- ====================== PRUEBAS DE CINEMATICA - SI FUNCIONA ===================== -->


  <xacro:arg name="jpac2_meshes_path" default="file:///home/leyla/Desktop/JPAC2/nexus-ros2/jpac2_ws/src/robot_description/meshes/visual"/>
  <xacro:property name="meshes_path" value="$(arg jpac2_meshes_path)"/>


  <link name="base_footprint"/>
  <joint name="base_joint" type="fixed">
    <parent link="base_footprint"/>
    <child  link="base_link"/>
    <origin xyz="0 0 0.010" rpy="0 0 0"/>
  </joint>


  <link name="base_link">
    <visual>
      <origin xyz="0 0 0.100" rpy="0 0 1.5708"/> 
      <geometry>
        <mesh filename="${meshes_path}/base_link.STL"/>
      </geometry>
      <material name="dark"/>
    </visual>
    <collision>
      <origin xyz="-0.064 0 0.047" rpy="0 0 0"/>
      <geometry><box size="0.266 0.266 0.094"/></geometry>
    </collision>
    <inertial>
      <origin xyz="0 0 0" rpy="0 0 0"/>
      <mass value="40.3729096"/>
      <inertia ixx="0.0087" ixy="0.0" ixz="0.0" 
      iyy="0.0086" iyz="0.0" izz="0.0146"/>
    </inertial>
  </link>



  <joint name="RuedaIzquierda_joint" type="continuous">
    <parent link="base_link"/>
    <child link="RuedaIzquierda_link"/>
    <origin xyz="0.0 0.144 0.023" rpy="-1.57 0 0"/><axis xyz="0 0 1"/>
  </joint>

  <link name="RuedaIzquierda_link">
    <visual>
      <origin xyz="0 0 0" rpy="0 0 0"/>
      <geometry><mesh filename="${meshes_path}/RuedaIzquierda_Link.STL"/>
      </geometry>
      <material name="black"/>
    </visual>
    <collision><origin xyz="0 0 0"/><geometry>
    <cylinder length="0.018" radius="0.033"/>
    </geometry></collision>
    <inertial>
    <origin xyz="0 0 0"/>
    <mass value="10.0285"/>
    <inertia ixx="1.12e-5" ixy="0" ixz="0" iyy="1.12e-5" iyz="0" izz="2.07e-5"/></inertial>
  </link>

  <joint name="RuedaDerecha_joint" type="continuous">
    <parent link="base_link"/>
    <child link="RuedaDerecha_link"/>
    <origin xyz="0.0 -0.144 0.023" rpy="-1.57 0 0"/><axis xyz="0 0 1"/>
  </joint>

  <link name="RuedaDerecha_link">
    <visual>
      <origin xyz="0 0 0" rpy="0 0 0"/>
      <geometry><mesh filename="${meshes_path}/RuedaDerecha_Link.STL"/></geometry>
      <material name="black"/>
    </visual>
    <collision><origin xyz="0 0 0"/>
    <geometry><cylinder length="0.018" radius="0.033"/>
    </geometry></collision>
    <inertial>
    <origin xyz="0 0 0"/>
    <mass value="10.0285"/>
    <inertia ixx="1.12e-5" ixy="0" ixz="0" iyy="1.12e-5" iyz="0" izz="2.07e-5"/></inertial>
  </link>



  <joint name="caster_back_right_joint" type="fixed">
    <parent link="base_link"/>
    <child link="caster_back_right_link"/>
    <origin xyz="-0.177 -0.064 -0.004" rpy="-1.57 0 0"/>
  </joint>
  <link name="caster_back_right_link">
    <collision><origin xyz="0 0.001 0"/>
    <geometry><box size="0.030 0.009 0.020"/>
    </geometry></collision>
    <inertial><origin xyz="0 0 0"/>
    <mass value="0.005"/>
    <inertia ixx="1e-3" ixy="0" ixz="0" iyy="1e-3" iyz="0" izz="1e-3"/></inertial>
  </link>

  <joint name="caster_back_left_joint" type="fixed">
    <parent link="base_link"/>
    <child link="caster_back_left_link"/>
    <origin xyz="-0.177 0.064 -0.004" rpy="-1.57 0 0"/>
  </joint>
  <link name="caster_back_left_link">
    <collision><origin xyz="0 0.001 0"/>
    <geometry><box size="0.030 0.009 0.020"/>
    </geometry></collision>
    <inertial><origin xyz="0 0 0"/>
    <mass value="0.005"/>
    <inertia ixx="1e-3" ixy="0" ixz="0" iyy="1e-3" iyz="0" izz="1e-3"/></inertial>
  </link>

  <joint name="imu_joint" type="fixed">
    <parent link="base_link"/>
    <child link="imu_link"/>
    <origin xyz="0.0 0 0.068" rpy="0 0 0"/>
  </joint>
  <link name="imu_link"/>
  <gazebo reference="imu_link">
    <sensor name="tb3_imu" type="imu">
      <always_on>true</always_on>
      <update_rate>200</update_rate>
      <visualize>false</visualize>
      <imu>
        <angular_velocity>
          <x><noise type="gaussian"><mean>0.0</mean><stddev>2e-4</stddev></noise></x>
          <y><noise type="gaussian"><mean>0.0</mean><stddev>2e-4</stddev></noise></y>
          <z><noise type="gaussian"><mean>0.0</mean><stddev>2e-4</stddev></noise></z>
        </angular_velocity>
        <linear_acceleration>
          <x><noise type="gaussian"><mean>0.0</mean><stddev>1.7e-2</stddev></noise></x>
          <y><noise type="gaussian"><mean>0.0</mean><stddev>1.7e-2</stddev></noise></y>
          <z><noise type="gaussian"><mean>0.0</mean><stddev>1.7e-2</stddev></noise></z>
        </linear_acceleration>
      </imu>
      <plugin name="imu_plugin" filename="libgazebo_ros_imu_sensor.so">
        <ros><remapping>~/out:=imu</remapping></ros>
      </plugin>
    </sensor>
  </gazebo>

  <joint name="scan_joint" type="fixed">
    <parent link="base_link"/>
    <child link="base_scan"/>
    <origin xyz="-0.064 0 0.95" rpy="0 0 0"/>
  </joint>
  <link name="base_scan">
    <visual>
      <origin xyz="0 0 0"/>
      <geometry><box size="0.05 0.05 0.06"/>
      </geometry><material name="grey"/>
    </visual>
    <collision><origin xyz="0 0 0"/>
    <geometry><box size="0.05 0.05 0.06"/>
    </geometry></collision>
    <inertial><origin xyz="0 0 0"/>
    <mass value="0.3"/>
    <inertia ixx="5e-4" ixy="0" ixz="0" iyy="5e-4" iyz="0" izz="5e-4"/></inertial>
  </link>

  <gazebo reference="base_scan">
    <sensor name="lidar_3d" type="ray">
      <pose>0 0 0 0 0 0</pose>
      <always_on>true</always_on>
      <visualize>false</visualize>
      <update_rate>10</update_rate>
      <ray>
        <scan>
          <horizontal><samples>1024</samples>
          <resolution>1</resolution>
          <min_angle>-3.14159</min_angle>
          <max_angle> 3.14159</max_angle></horizontal>
          <vertical><samples>32</samples>
          <resolution>1</resolution>
          <min_angle>0.0</min_angle>
          <max_angle>1.57079632679</max_angle></vertical>
        </scan>
        <range><min>0.50</min>
        <max>3.0</max>
        <resolution>0.01</resolution></range>
        <noise><type>gaussian</type>
        <mean>0.0</mean>
        <stddev>0.01</stddev></noise>
      </ray>
      <plugin name="lidar_3d_points" filename="libgazebo_ros_ray_sensor.so">
        <ros><remapping>~/out:=points2</remapping></ros>
        <output_type>sensor_msgs/PointCloud2</output_type>
        <frame_name>base_scan</frame_name>
      </plugin>
    </sensor>
  </gazebo>

  <gazebo>
    <plugin name="diff_drive" filename="libgazebo_ros_diff_drive.so">

      <ros><remapping>cmd_vel:=cmd_vel</remapping>
      <remapping>odom:=odom</remapping></ros>
      <update_rate>30</update_rate>

      <left_joint>RuedaIzquierda_joint</left_joint>
      <right_joint>RuedaDerecha_joint</right_joint>

      <wheel_separation>0.287</wheel_separation>
      <wheel_diameter>0.066</wheel_diameter>

      <publish_odom>true</publish_odom>
      <publish_odom_tf>true</publish_odom_tf>
      <publish_wheel_tf>false</publish_wheel_tf>

      <odometry_frame>odom</odometry_frame>
      <robot_base_frame>base_footprint</robot_base_frame>
      <max_wheel_torque>10</max_wheel_torque>
      <max_wheel_acceleration>1.0</max_wheel_acceleration>

    </plugin>
  </gazebo>

  <gazebo>
    <plugin name="joint_state_pub" filename="libgazebo_ros_joint_state_publisher.so">

      <ros><remapping>~/out:=joint_states</remapping></ros>

      <update_rate>30</update_rate>
      <joint_name>RuedaIzquierda_joint</joint_name>
      <joint_name>RuedaDerecha_joint</joint_name>
      
    </plugin>
  </gazebo>

</robot>